Workbook

Sheet Duplicada
C2: Grupo 1 | H2: Rango de edad: 19 a 30 | N2: Grupo 2 | S2: Rango de edad: 31-50 años | X2: Grupo 3 | AC2: Rango de edad: +50
D4: Grupo | E4: Alimento | F4: Unidad de medida por porción | G4: Medida casera | H4: Gramos porción | I4: Porción elegida | J4: Unidades | K4: Porción final | L4: Cantidad total gramos | O4: Grupo | P4: Alimento | Q4: Unidad de medida | R4: Medida casera | S4: Gramos porción | T4: Cantidad consumida | U4: Porción final | V4: Cantidad total gramos | Y4: Grupo | Z4: Alimento | AA4: Unidad de medida | AB4: Medida casera | AC4: Gramos porción | AD4: Cantidad consumida | AE4: Porción final | AF4: Cantidad total gramos
C5: Desayuno | D5: Frutas | E5: Fresa | F5: 9 | G5: unidades | H5: 161 | I5: 0.5 | K5: =IF(I5=0,(J5/F5),I5) -> 0.5 | L5: =K5*H5 -> 80.5 | N5: Desayuno | O5: Frutas | P5: Fresa | Q5: 9 | R5: unidades | S5: 161 | T5: 3 | U5: =+T5/Q5 -> 0.33333333 | V5: =S5*U5 -> 53.666667 | X5: Desayuno | Z5: Agua | AA5: 1 | AB5: Vaso de tinto | AD5: 1 | AE5: =+AD5/AA5 -> 1 | AF5: =AC5*AE5 -> 0
D6: Grasas | E6: Tajada de queso | F6: 1 | G6: Tajada | H6: 20 | I6: 1 | K6: =IF(I6=0,(J6/F6),I6) -> 1 | L6: =H6*K6 -> 20 | P6: Arepa | Q6: 1 | R6: Unidad grande | S6: 52 | T6: 1 | U6: =+T6/Q6 -> 1 | V6: =S6*U6 -> 52 | Z6: Huevo cocido | AA6: 1 | AB6: unidad | AC6: 50 | AD6: 2 | AE6: =+AD6/AA6 -> 2 | AF6: =AC6*AE6 -> 100
D7: Leguminosas | E7: Banano | F7: 1 | G7: Unidad pequeña | H7: 65 | I7: 1 | K7: =IF(I7=0,(J7/F7),I7) -> 1 | L7: =H7*I7 -> 65 | P7: Huevos | Q7: 1 | R7: Unidad | S7: 50 | T7: 2 | U7: =+T7/Q7 -> 2 | V7: =S7*T7 -> 100 | Z7: Arepa | AA7: 1 | AB7: unidad grande | AC7: 52 | AD7: 1 | AE7: =+AD7/AA7 -> 1 | AF7: =AC7*AD7 -> 52
D8: Carnes | E8: Huevo | F8: 1 | G8: unidad | H8: 50 | I8: 2 | K8: =IF(I8=0,(J8/F8),I8) -> 2 | L8: =H8*K8 -> 100 | P8: Cuajada | Q8: 1 | R8: Tajada pequeña semi gruesa | T8: 50 | U8: =+T8/Q8 -> 50 | V8: =S8*U8 -> 0 | AE8: =+AD8/AA8 -> #DIV/0! | AF8: =AC8*AE8 -> #DIV/0!
E9: Pan integral | F9: 1 | G9: tajada mediana | H9: 32 | I9: 1 | K9: =IF(I9=0,(J9/F9),I9) -> 1 | L9: =H9*K9 -> 32 | P9: Jugo de naranja | Q9: 1 | R9: Vaso pequeño | T9: 1 | U9: =+T9/Q9 -> 1 | V9: =S9*U9 -> 0 | AE9: =+AD9/AA9 -> #DIV/0! | AF9: =AC9*AE9 -> #DIV/0!
U10: =+T10/Q10 -> #DIV/0! | V10: =S10*U10 -> #DIV/0! | AE10: =+AD10/AA10 -> #DIV/0! | AF10: =AC10*AE10 -> #DIV/0!
U11: =+T11/Q11 -> #DIV/0! | V11: =S11*U11 -> #DIV/0! | AE11: =+AD11/AA11 -> #DIV/0! | AF11: =AC11*AE11 -> #DIV/0!
U12: =+T12/Q12 -> #DIV/0! | V12: =S12*U12 -> #DIV/0! | AE12: =+AD12/AA12 -> #DIV/0! | AF12: =AC12*AE12 -> #DIV/0!
C13: Almuerzo | E13: Pechuga de pollo | F13: 1 | G13: Unidad | H13: 80 | I13: 1 | K13: =IF(I13=0,(J13/F13),I13) -> 1 | L13: =H13*K13 -> 80 | N13: Almuerzo | P13: Arroz | Q13: 6 | R13: Cucharadas soperas | S13: 80 | T13: 1 | U13: =+T13/Q13 -> 0.16666667 | V13: =S13*U13 -> 13.333333 | X13: Almuerzo | Z13: Agua | AA13: 1 | AB13: Vaso de tinto | AD13: 1 | AE13: =+AD13/AA13 -> 1 | AF13: =AC13*AE13 -> 0
E14: Tomates cherry | G14: Unidades | I14: 4 | K14: =IF(I14=0,(J14/F14),I14) -> 4 | L14: =H14*K14 -> 0 | P14: Lentejas | Q14: 1 | R14: Cucharon colmado | S14: 130 | T14: 1 | U14: =+T14/Q14 -> 1 | V14: =S14*U14 -> 130 | Z14: Papa cocida | AA14: 1 | AB14: unidad mediana | AC14: 83 | AD14: 2 | AE14: =+AD14/AA14 -> 2 | AF14: =AC14*AE14 -> 166
E15: Papas criollas | F15: 1 | G15: Unidades | H15: 105 | I15: 5 | K15: =IF(I15=0,(J15/F15),I15) -> 5 | L15: =H15*K15 -> 525 | P15: Huevos | Q15: 1 | R15: Unidad | S15: 50 | T15: 1 | U15: =+T15/Q15 -> 1 | V15: =S15*U15 -> 50 | Z15: Lentejas | AA15: 1 | AB15: cucharon colmado | AC15: 130 | AD15: 1 | AE15: =+AD15/AA15 -> 1 | AF15: =AC15*AE15 -> 130
E16: Lechuga | F16: 1 | G16: Hoja | I16: 2 | K16: =IF(I16=0,(J16/F16),I16) -> 2 | L16: =H16*K16 -> 0 | M16: TC | P16: Ensalada | R16: T.C | T16: 1 | U16: =+T16/Q16 -> #DIV/0! | V16: =S16*U16 -> #DIV/0! | Z16: Aguacate | AA16: 1 | AB16: unidad | AC16: 30 | AD16: 1 | AE16: =+AD16/AA16 -> 1 | AF16: =AC16*AE16 -> 30
E17: Aguacate | F17: =1/8 -> 0.125 | G17: unidad mediana | H17: 30 | I17: 1 | K17: =IF(I17=0,(J17/F17),I17) -> 1 | L17: =H17*K17 -> 30 | P17: Pollo | Q17: 1 | R17: Unidad mediana | S17: 75 | T17: 1 | U17: =+T17/Q17 -> 1 | V17: =S17*U17 -> 75 | Z17: Lechuga | AA17: 1 | AB17: hoja | AD17: 1 | AE17: =+AD17/AA17 -> 1 | AF17: =AC17*AE17 -> 0 | AG17: TC
E18: Zanahoria | F18: 1 | G18: Unidad | H18: 58 | I18: 3 | K18: =IF(I18=0,(J18/F18),I18) -> 3 | L18: =H18*K18 -> 174 | P18: Jugo de guayaba | Q18: 1 | R18: Vaso mediano | U18: =+T18/Q18 -> 0 | V18: =S18*U18 -> 0 | Z18: Tomate | AA18: 1 | AB18: unidad pequeña | AC18: 132 | AD18: 1 | AE18: =+AD18/AA18 -> 1 | AF18: =AC18*AE18 -> 132
E19: Cilantro | G19: Ramas | I19: 1 | K19: =IF(I19=0,(J19/F19),I19) -> 1 | L19: =H19*K19 -> 0 | P19: Aguacate | Q19: 1 | R19: Unidad mediana | S19: 30 | T19: 1 | U19: =+T19/Q19 -> 1 | V19: =S19*U19 -> 30 | Z19: Zanahoria | AA19: 1 | AB19: unidad | AC19: 58 | AD19: 0.5 | AE19: =+AD19/AA19 -> 0.5 | AF19: =AC19*AE19 -> 29
K20: =IF(I20=0,(J20/F20),I20) -> #DIV/0! | L20: =H20*K20 -> #DIV/0! | U20: =+T20/Q20 -> #DIV/0! | V20: =S20*U20 -> #DIV/0! | Z20: Pollo | AA20: 1 | AB20: unidad | AC20: 80 | AD20: 1 | AE20: =+AD20/AA20 -> 1 | AF20: =AC20*AE20 -> 80
C21: Comida | E21: Camarones | F21: 1 | G21: Porción | H21: 300 | I21: 1 | K21: =IF(I21=0,(J21/F21),I21) -> 1 | L21: =H21*K21 -> 300 | N21: Comida | P21: Pollo | Q21: 1 | R21: Unidad grande | S21: 80 | T21: 1 | U21: =+T21/Q21 -> 1 | V21: =S21*U21 -> 80 | X21: Comida | Z21: Cebolla | AE21: =+AD21/AA21 -> #DIV/0! | AF21: =AC21*AE21 -> #DIV/0!
E22: Brócoli | F22: 1 | G22: Unidad | H22: 89 | I22: 1 | K22: =IF(I22=0,(J22/F22),I22) -> 1 | L22: =H22*K22 -> 89 | P22: Papa criolla | Q22: 3 | R22: Unidades | S22: 108 | T22: 1 | U22: =+T22/Q22 -> 0.33333333 | V22: =S22*U22 -> 36 | Z22: Carne de cerdo | AA22: 1 | AB22: unidad | AC22: 100 | AD22: 1 | AE22: =+AD22/AA22 -> 1 | AF22: =AC22*AE22 -> 100
E23: Pan integral | F23: 1 | G23: tajada mediana | H23: 65 | I23: 1 | K23: =IF(I23=0,(J23/F23),I23) -> 1 | L23: =H23*K23 -> 65 | P23: Ensalada | R23: T.C | U23: =+T23/Q23 -> #DIV/0! | V23: =S23*U23 -> #DIV/0! | Z23: Zanahoria | AA23: 1 | AB23: unidad | AC23: 58 | AD23: 0.5 | AE23: =+AD23/AA23 -> 0.5 | AF23: =AC23*AE23 -> 29
E24: Papa | F24: 2 | G24: Unidad | H24: 83 | I24: 2 | K24: =IF(I24=0,(J24/F24),I24) -> 2 | L24: =H24*K24 -> 166 | P24: Infusión frutas | Q24: 1 | R24: Vaso pequeño | T24: 1 | U24: =+T24/Q24 -> 1 | V24: =S24*U24 -> 0 | Z24: Arverjas | AA24: 1 | AB24: cucharon colmado | AE24: =+AD24/AA24 -> 0 | AF24: =AC24*AE24 -> 0
E25: Pimienta | F25: 2 | G25: Cucharaditas | I25: 2 | K25: =IF(I25=0,(J25/F25),I25) -> 2 | L25: =H25*K25 -> 0 | U25: =+T25/Q25 -> #DIV/0! | V25: =S25*U25 -> #DIV/0! | Z25: Platano asado | AA25: 1 | AB25: unidad (1/4 del platano) | AC25: 66 | AD25: 2 | AE25: =+AD25/AA25 -> 2 | AF25: =AC25*AE25 -> 132
E26: Perejil | F26: 1 | G26: Rama | I26: 1 | K26: =IF(I26=0,(J26/F26),I26) -> 1 | L26: =H26*K26 -> 0 | U26: =+T26/Q26 -> #DIV/0! | V26: =S26*U26 -> #DIV/0! | Z26: Pimenton | AA26: 1 | AB26: unidad | AD26: 0.5 | AE26: =+AD26/AA26 -> 0.5 | AF26: =AC26*AE26 -> 0
E27: Limon mediano | F27: 1 | G27: Unidad | I27: 1 | K27: =IF(I27=0,(J27/F27),I27) -> 1 | L27: =H27*K27 -> 0 | U27: =+T27/Q27 -> #DIV/0! | V27: =S27*U27 -> #DIV/0! | Z27: Apio | AA27: 1 | AB27: tallo | AD27: 1 | AE27: =+AD27/AA27 -> 1 | AF27: =AC27*AE27 -> 0
E28: Panela molida | F28: 1 | G28: Cucharrada | I28: 1 | K28: =IF(I28=0,(J28/F28),I28) -> 1 | L28: =H28*K28 -> 0 | U28: =+T28/Q28 -> #DIV/0! | V28: =S28*U28 -> #DIV/0! | AE28: =+AD28/AA28 -> #DIV/0! | AF28: =AC28*AE28 -> #DIV/0!
K29: =IF(I29=0,(J29/F29),I29) -> #DIV/0! | L29: =H29*K29 -> #DIV/0! | U29: =+T29/Q29 -> #DIV/0! | V29: =S29*U29 -> #DIV/0! | AE29: =+AD29/AA29 -> #DIV/0! | AF29: =AC29*AE29 -> #DIV/0!
C30: Algo | E30: Yogur griego | F30: 1 | G30: Unidad | H30: 200 | I30: 1 | K30: =IF(I30=0,(J30/F30),I30) -> 1 | L30: =H30*K30 -> 200 | N30: Extra 1 (Media mañana) | P30: Yogurt griego | Q30: 0.5 | R30: Vaso pequeño | T30: 1 | U30: =+T30/Q30 -> 2 | V30: =S30*U30 -> 0 | X30: Media mañana | Z30: Mani | AA30: 1 | AB30: puñado | AE30: =+AD30/AA30 -> 0 | AF30: =AC30*AE30 -> 0
E31: Mango | F31: 1 | G31: Unidad | H31: 112 | I31: 1 | K31: =IF(I31=0,(J31/F31),I31) -> 1 | L31: =H31*K31 -> 112 | P31: Frutos secos | Q31: 4 | R31: Cucharadas | T31: 1 | U31: =+T31/Q31 -> 0.25 | V31: =S31*U31 -> 0 | Z31: Nuez | AA31: 1 | AB31: puñado | AE31: =+AD31/AA31 -> 0 | AF31: =AC31*AE31 -> 0
E32: Granola | F32: 1 | G32: Cucharas | H32: 50 | I32: 1 | K32: =IF(I32=0,(J32/F32),I32) -> 1 | L32: =H32*K32 -> 50 | P32: Ensalada de fruta (manzana verde, melón, papaya, piña) | Q32: 1 | R32: Vaso pequeño | U32: =+T32/Q32 -> 0 | V32: =S32*U32 -> 0 | Z32: Almendras | AA32: 1 | AB32: puñado | AE32: =+AD32/AA32 -> 0 | AF32: =AC32*AE32 -> 0
E33: Crema de maní | F33: 1 | G33: Cucharadas dulceras | H33: 5 | I33: 2 | K33: =IF(I33=0,(J33/F33),I33) -> 2 | L33: =H33*K33 -> 10 | U33: =+T33/Q33 -> #DIV/0! | V33: =S33*U33 -> #DIV/0! | Z33: Kiwi | AA33: 1 | AB33: unidad | AE33: =+AD33/AA33 -> 0 | AF33: =AC33*AE33 -> 0
E34: Avena | F34: 3 | G34: Cucharas soperas | H34: 18 | I34: 1 | K34: =IF(I34=0,(J34/F34),I34) -> 1 | L34: =H34*K34 -> 18 | U34: =+T34/Q34 -> #DIV/0! | V34: =S34*U34 -> #DIV/0! | Z34: Piña | AA34: 1 | AB34: rodaja | AC34: 110 | AD34: 1 | AE34: =+AD34/AA34 -> 1 | AF34: =AC34*AE34 -> 110
K35: =+I35/F35 -> #DIV/0! | L35: =H35*K35 -> #DIV/0! | U35: =+T35/Q35 -> #DIV/0! | V35: =S35*U35 -> #DIV/0! | Z35: Manzana | AA35: 1 | AB35: unidad pequeña | AC35: 112 | AD35: 1 | AE35: =+AD35/AA35 -> 1 | AF35: =AC35*AE35 -> 112
K36: =+I36/F36 -> #DIV/0! | L36: =H36*K36 -> #DIV/0! | U36: =+T36/Q36 -> #DIV/0! | V36: =S36*U36 -> #DIV/0! | Z36: Fresas | AA36: 9 | AB36: unidades | AC36: 161 | AD36: 6 | AE36: =+AD36/AA36 -> 0.66666667 | AF36: =AC36*AE36 -> 107.33333
C37: Extra 2 | K37: =+I37/F37 -> #DIV/0! | L37: =H37*K37 -> #DIV/0! | N37: Extra 2 (Algo) | P37: Gelatina | Q37: 1 | R37: Vaso grande | T37: 1 | U37: =+T37/Q37 -> 1 | V37: =S37*U37 -> 0 | X37: Por la tarde | Z37: Mani | AA37: 1 | AB37: puñado | AE37: =+AD37/AA37 -> 0 | AF37: =AC37*AE37 -> 0
K38: =+I38/F38 -> #DIV/0! | L38: =H38*K38 -> #DIV/0! | U38: =+T38/Q38 -> #DIV/0! | V38: =S38*U38 -> #DIV/0! | Z38: Nuez | AA38: 1 | AB38: puñado | AE38: =+AD38/AA38 -> 0 | AF38: =AC38*AE38 -> 0
K39: =+I39/F39 -> #DIV/0! | L39: =H39*K39 -> #DIV/0! | U39: =+T39/Q39 -> #DIV/0! | V39: =S39*U39 -> #DIV/0! | Z39: Almendras | AA39: 1 | AB39: puñado | AE39: =+AD39/AA39 -> 0 | AF39: =AC39*AE39 -> 0
K40: =+I40/F40 -> #DIV/0! | L40: =H40*K40 -> #DIV/0! | U40: =+T40/Q40 -> #DIV/0! | V40: =S40*U40 -> #DIV/0! | Z40: Kiwi | AA40: 1 | AB40: unidad | AE40: =+AD40/AA40 -> 0 | AF40: =AC40*AE40 -> 0
K41: =+I41/F41 -> #DIV/0! | L41: =H41*K41 -> #DIV/0! | U41: =+T41/Q41 -> #DIV/0! | V41: =S41*U41 -> #DIV/0! | Z41: Piña | AA41: 1 | AB41: rodaja | AC41: 110 | AD41: 1 | AE41: =+AD41/AA41 -> 1 | AF41: =AC41*AE41 -> 110
K42: =+I42/F42 -> #DIV/0! | L42: =H42*K42 -> #DIV/0! | U42: =+T42/Q42 -> #DIV/0! | V42: =S42*U42 -> #DIV/0! | Z42: Manzana | AA42: 1 | AB42: unidad pequeña | AC42: 112 | AD42: 1 | AE42: =+AD42/AA42 -> 1 | AF42: =AC42*AE42 -> 112
...

Sheet Diccionario de datos
A1: Diccionario de datos
A2: Variable | B2: Descripción
A3: Información sociodemografica
A4: ID | B4: Identificación de los sujetos por grupo de edad y región 1 - 3 = Medellín 4 - 6 =Guarne 7 - 9 = Santa Rosa ID 1,4,7: 19 - 30 ID 2,5,8: 31 - 50 ID 3,6,9: +51
A5: Region | B5: Regiones donde se llevo a cabo el estudio
A6: Grupo | B6: Grupo de edad
A7: Edad
A8: Genero
A9: Estrato
A10: Educación | B10: Nivel de educación Primaria - secundaria = 1 Universitario, profesional = 2 Posgrado = 3
A11: Ocupacion
A12: Estado civil
A13: Gramaje
A14: Plato | B14: Momento del día donde se consumen los alimentos
A15: Grupo | B15: Grupo del alimento
A16: Alimento
A17: Unidad de medida por porción | B17: Porciones establecidas en tablas nutricionales para el alimento
A18: Medida casera | B18: Unidad de medida casera establecida en tablas nutricionales
A19: Gramos porción | B19: Gramos correspondientes a la unidad de medida por porción
A20: Porción elegida | B20: Cantidad del alimento con respecto a la porción establecida en tablas nutricionales
A21: Unidades | B21: Unidades del alimento con respecto a la porción establecida en tablas nutricionales
A22: Porción final
A23: Cantidad total gramos | B23: Gramos del alimento escogido
A24: Observaciones
A25: Puntaje dietas
A26: Puntaje | B26: Puntaje de 1 a 5 establecido por los participantes ante la pregunta: "Cómo calificaría su almuerzo real?" (En terminos de que tan saludable es)

Sheet Información sociodemografica
A1: ID | B1: Region | C1: Grupo | D1: Edad | E1: Genero | F1: Estrato | G1: Nivel de educación | H1: Educación | I1: Ocupacion | J1: Estado civil
A2: 1 | B2: Medellin | C2: 19 - 30 | D2: 21 | E2: 1 | F2: 4 | G2: Profesional | H2: 2 | I2: Estudiante | J2: Soltero
A3: 1 | B3: Medellin | C3: 19 - 30 | D3: 24 | E3: 1 | F3: 5 | G3: Profesional | H3: 2 | I3: Estudiante | J3: Soltero
A4: 1 | B4: Medellin | C4: 19 - 30 | D4: 27 | E4: 1 | F4: 4 | G4: Tecnico | H4: 2 | I4: Estudiante | J4: Soltero
A5: 1 | B5: Medellin | C5: 19 - 30 | D5: 30 | E5: 0 | F5: 4 | G5: PhD | H5: 3 | I5: Cyber seguridad | J5: Soltero
A6: 1 | B6: Medellin | C6: 19 - 30 | D6: 30 | E6: 0 | F6: 3 | G6: Profesional | H6: 2 | I6: Empleada | J6: Soltero
A7: 2 | B7: Medellin | C7: 31 - 50 | D7: 37 | E7: 1 | F7: 3 | G7: Universitario | H7: 2 | I7: Independiente | J7: Unión libre
A8: 2 | B8: Medellin | C8: 31 - 50 | D8: 38 | E8: 1 | F8: 2 | G8: Tecnico | H8: 2 | I8: Trabajador | J8: Soltero
A9: 2 | B9: Medellin | C9: 31 - 50 | D9: 40 | E9: 1 | F9: 2 | G9: Tecnico | H9: 2 | I9: Independiente | J9: Soltero
A10: 2 | B10: Medellin | C10: 31 - 50 | D10: 40 | E10: 0 | F10: 3 | G10: Universitario | H10: 2 | I10: Estudiante | J10: Soltero
A11: 2 | B11: Medellin | C11: 31 - 50 | D11: 42 | E11: 0 | F11: 3 | G11: Bachiller | H11: 2 | I11: Trabajador | J11: Soltero
A12: 3 | B12: Medellin | C12: +51 | D12: 53 | E12: 1 | F12: 4 | G12: Universitario | H12: 2 | I12: Administrador | J12: Separado
A13: 3 | B13: Medellin | C13: +51 | D13: 53 | E13: 0 | F13: 3 | G13: Universitario | H13: 2 | I13: Independiente | J13: Casado
... A27: 6 | B27: Guarne | C27: +51 | D27: 68 | E27: 0 | F27: 3 | G27: Primaria | H27: 1 | I27: Agricultor independiente | J27: Casado
A28: 6 | B28: Guarne | C28: +51 | D28: 75 | E28: 0 | F28: 3 | I28: Tesorero | J28: Casado
A29: 7 | B29: Santa Rosa | C29: 19 - 30 | D29: 21 | E29: 0 | F29: 3 | G29: Bachiller | H29: 2 | I29: Independiente | J29: Soltero
A30: 7 | B30: Santa Rosa | C30: 19 - 30 | D30: 22 | E30: 1 | F30: 1 | G30: Bachiller | H30: 2 | I30: Ama de casa | J30: Union Libre
A31: 7 | B31: Santa Rosa | C31: 19 - 30 | D31: 22 | E31: 1 | F31: 1 | G31: Bachiller | H31: 2 | I31: Independiente | J31: Union Libre
A32: 7 | B32: Santa Rosa | C32: 19 - 30 | D32: 23 | E32: 1 | F32: 1 | G32: Bachiller | H32: 2 | I32: Ama de casa | J32: Union Libre
A33: 7 | B33: Santa Rosa | C33: 19 - 30 | D33: 28 | E33: 1 | F33: 3 | G33: Bachiller | H33: 2 | I33: Independiente | J33: Soltero
A34: 7 | B34: Santa Rosa | C34: 19 - 30 | D34: 30 | E34: 1 | F34: 1 | G34: Bachiller | H34: 2 | I34: Ama de casa | J34: Casado
A35: 8 | B35: Santa Rosa | C35: 31 - 50 | D35: 40 | E35: 1 | F35: 1 | G35: Bachiller/Tecnico | H35: 2 | I35: Ama de casa | J35: Soltero
A36: 8 | B36: Santa Rosa | C36: 31 - 50 | D36: 42 | E36: 1 | F36: 5 | G36: Especialización | H36: 3 | I36: Independiente | J36: Casado
A37: 8 | B37: Santa Rosa | C37: 31 - 50 | D37: 45 | E37: 1 | F37: 2 | G37: Tecnologa | H37: 2 | I37: Apoyo unidad productiva | J37: Soltera
A38: 8 | B38: Santa Rosa | C38: 31 - 50 | D38: 48 | E38: 0 | F38: 3 | G38: Profesional | H38: 2 | I38: Independiente | J38: Casado
A39: 9 | B39: Santa Rosa | C39: +51 | D39: 52 | E39: 1 | F39: 1 | G39: Primaria | H39: 1 | I39: Ama de casa | J39: Casado
A40: 9 | B40: Santa Rosa | C40: +51 | D40: 61 | E40: 0 | F40: 2 | G40: Primaria | H40: 1 | I40: Agricultor | J40: Casado
... A42: 9 | B42: Santa Rosa | C42: +51 | D42: 67 | E42: 0 | F42: 4 | G42: Profesional | H42: 2 | I42: Secretaria | J42: Casado
A43: Genero: M = 0, F = 1
A44: Educación: Primaria - secundaria: 1, universitario, profesional = 2, posgrado: 3

Sheet Gramaje
A1: ID | B1: Region | C1: Grupo | D1: Plato | E1: Grupo alimentario | F1: Alimento | G1: Unidad de medida por porción | H1: Medida casera | I1: Gramos porción | J1: Porción elegida | K1: Unidades | L1: Porción final | M1: Cantidad total gramos | N1: Observaciones | O1: Calorias por porción LI kcal | P1: Calorias porción elegida | Q1: Proteina por porción LI prot | R1: Proteina porción elegida | S1: Carbohidratos por porción LI CHO | T1: Carbohidratos por porción elegida | U1: Grasas por porción LI GT | V1: Grasas por porción elegida | W1: Fibra por porción LI FD | X1: Fibra por porción elegida | Y1: Calcio por porción LI CA mg | Z1: Calcio por porción elegida | AA1: Hierro por porción LI FE | AB1: Hierro por porción elegida | AC1: Sodio por porción LI NA | AD1: Sodio por porción elegida | AE1: Se mencionan infusiones de frutas, agua como sobremesa para analisis cuali
A2: 1 | B2: Medellín | C2: 19 - 30 | D2: Almuerzo | E2: Grasas | F2: Aguacate | G2: =1/8 -> 0.125 | H2: unidad mediana | I2: 30 | J2: 1 | L2: =IF(J2=0,(K2/G2),J2) -> 1 | M2: =I2*L2 -> 30 | O2: 53 | P2: =(O2*M2)/I2 -> 53 | Q2: 0.6 | R2: =(Q2*M2)/I2 -> 0.6 | S2: 2.2 | T2: =(S2*M2)/I2 -> 2.2 | U2: 4.6 | V2: =(U2*M2)/I2 -> 4.6 | W2: 1.5 | X2: =(W2*M2)/I2 -> 1.5 | Y2: 3 | Z2: =(Y2*M2)/I2 -> 3 | AA2: 0.3 | AB2: =(AA2*M2)/I2 -> 0.3 | AC2: 3 | AD2: =(AC2*M2)/I2 -> 3
A3: 1 | B3: Medellín | C3: 19 - 30 | D3: Algo | E3: Bebidas no alcohólicas | F3: Avena | G3: 3 | H3: Cucharas soperas | I3: 18 | J3: 1 | L3: =IF(J3=0,(K3/G3),J3) -> 1 | M3: =I3*L3 -> 18 | N3: Avena instantanea saborizada | O3: 96 | P3: =(O3*M3)/I3 -> 96 | Q3: 1 | R3: =(Q3*M3)/I3 -> 1 | S3: 23 | T3: =(S3*M3)/I3 -> 23 | U3: 0 | V3: =(U3*M3)/I3 -> 0 | W3: 1 | X3: =(W3*M3)/I3 -> 1 | Y3: 25 | Z3: =(Y3*M3)/I3 -> 25 | AA3: 0.7 | AB3: =(AA3*M3)/I3 -> 0.7 | AC3: 20 | AD3: =(AC3*M3)/I3 -> 20
A4: 1 | B4: Medellín | C4: 19 - 30 | D4: Desayuno | E4: Frutas | F4: Banano | G4: 1 | H4: Unidad pequeña | I4: 65 | J4: 1 | L4: =IF(J4=0,(K4/G4),J4) -> 1 | M4: =I4*J4 -> 65 | O4: 66 | P4: =(O4*M4)/I4 -> 66 | Q4: 0.7 | R4: =(Q4*M4)/I4 -> 0.7 | S4: 15.2 | T4: =(S4*M4)/I4 -> 15.2 | U4: 0.3 | V4: =(U4*M4)/I4 -> 0.3 | W4: 1.6 | X4: =(W4*M4)/I4 -> 1.6 | Y4: 4 | Z4: =(Y4*M4)/I4 -> 4 | AA4: 0.2 | AB4: =(AA4*M4)/I4 -> 0.2 | AC4: 1 | AD4: =(AC4*M4)/I4 -> 1
A5: 1 | B5: Medellín | C5: 19 - 30 | D5: Comida | E5: Verduras y hortalizas | F5: Broccoli | G5: 1 | H5: Unidad | I5: 89 | J5: 1 | L5: =IF(J5=0,(K5/G5),J5) -> 1 | M5: =I5*L5 -> 89 | O5: 36 | P5: =(O5*M5)/I5 -> 36 | Q5: 2.7 | R5: =(Q5*M5)/I5 -> 2.7 | S5: 5.6 | T5: =(S5*M5)/I5 -> 5.6 | U5: 0.3 | V5: =(U5*M5)/I5 -> 0.3 | W5: 2.9 | X5: =(W5*M5)/I5 -> 2.9 | Y5: 28 | Z5: =(Y5*M5)/I5 -> 28 | AA5: 0.6 | AB5: =(AA5*M5)/I5 -> 0.6 | AC5: 20 | AD5: =(AC5*M5)/I5 -> 20
A6: 1 | B6: Medellín | C6: 19 - 30 | D6: Comida | E6: Carnes | F6: Camarones | G6: 1 | H6: Porción | I6: 300 | J6: 1 | L6: =IF(J6=0,(K6/G6),J6) -> 1 | M6: =I6*L6 -> 300 | O6: 73 | P6: =(O6*M6)/I6 -> 73 | Q6: 14.8 | R6: =(Q6*M6)/I6 -> 14.8 | S6: 0.7 | T6: =(S6*M6)/I6 -> 0.7 | U6: 1.2 | V6: =(U6*M6)/I6 -> 1.2 | W6: 0 | X6: =(W6*M6)/I6 -> 0 | Y6: 38 | Z6: =(Y6*M6)/I6 -> 38 | AA6: 1.8 | AB6: =(AA6*M6)/I6 -> 1.8 | AC6: 108 | AD6: =(AC6*M6)/I6 -> 108
A7: 1 | B7: Medellín | C7: 19 - 30 | D7: Almuerzo | E7: Hierbas, especias y condimentos | F7: Cilantro | G7: 1 | H7: hoja | I7: 100 | J7: 0.01 | L7: =IF(J7=0,(K7/G7),J7) -> 0.01 | M7: =I7*L7 -> 1 | O7: 2 | P7: =(O7*M7)/I7 -> 0.02 | Q7: 0.24 | R7: =(Q7*M7)/I7 -> 0.0024 | S7: 0.26 | T7: =(S7*M7)/I7 -> 0.0026 | U7: 0.06 | V7: =(U7*M7)/I7 -> 0.0006 | W7: 0.23 | X7: =(W7*M7)/I7 -> 0.0023 | Y7: 9.8 | Z7: =(Y7*M7)/I7 -> 0.098 | AA7: 0.2 | AB7: =(AA7*M7)/I7 -> 0.002 | AC7: 2.8 | AD7: =(AC7*M7)/I7 -> 0.028
A8: 1 | B8: Medellín | C8: 19 - 30 | D8: Algo | E8: Grasas | F8: Mantequilla de mani | G8: 1 | H8: Cucharadas dulceras | I8: 5 | J8: 2 | L8: =IF(J8=0,(K8/G8),J8) -> 2 | M8: =I8*L8 -> 10 | O8: 51 | P8: =(O8*M8)/I8 -> 102 | Q8: 2 | R8: =(Q8*M8)/I8 -> 4 | S8: 1.5 | T8: =(S8*M8)/I8 -> 3 | U8: 4.1 | V8: =(U8*M8)/I8 -> 8.2 | W8: 0.5 | X8: =(W8*M8)/I8 -> 1 | Y8: 3 | Z8: =(Y8*M8)/I8 -> 6 | AA8: 0.1 | AB8: =(AA8*M8)/I8 -> 0.2 | AC8: 37 | AD8: =(AC8*M8)/I8 -> 74
A9: 1 | B9: Medellín | C9: 19 - 30 | D9: Desayuno | E9: Frutas | F9: Fresa | G9: 9 | H9: unidades | I9: 161 | J9: 0.5 | L9: =IF(J9=0,(K9/G9),J9) -> 0.5 | M9: =L9*I9 -> 80.5 | O9: 55 | P9: =(O9*M9)/I9 -> 27.5 | Q9: 1.3 | R9: =(Q9*M9)/I9 -> 0.65 | S9: 11.1 | T9: =(S9*M9)/I9 -> 5.55 | U9: 0.6 | V9: =(U9*M9)/I9 -> 0.3 | W9: 3.7 | X9: =(W9*M9)/I9 -> 1.85 | Y9: 45 | Z9: =(Y9*M9)/I9 -> 22.5 | AA9: 1.3 | AB9: =(AA9*M9)/I9 -> 0.65 | AC9: 2 | AD9: =(AC9*M9)/I9 -> 1
A10: 1 | B10: Medellín | C10: 19 - 30 | D10: Algo | E10: Cereales, raíces, tubérculos y plátanos | F10: Granola | G10: 1 | H10: Cucharas | I10: 50 | J10: 1 | L10: =IF(J10=0,(K10/G10),J10) -> 1 | M10: =I10*L10 -> 50 | P10: =(O10*M10)/I10 -> 0 | R10: =(Q10*M10)/I10 -> 0 | T10: =(S10*M10)/I10 -> 0 | V10: =(U10*M10)/I10 -> 0 | X10: =(W10*M10)/I10 -> 0 | Z10: =(Y10*M10)/I10 -> 0 | AB10: =(AA10*M10)/I10 -> 0 | AD10: =(AC10*M10)/I10 -> 0
A11: 1 | B11: Medellín | C11: 19 - 30 | D11: Desayuno | E11: Sustitutos | F11: Huevo | G11: 1 | H11: unidad | I11: 50 | J11: 2 | L11: =IF(J11=0,(K11/G11),J11) -> 2 | M11: =I11*L11 -> 100 | N11: Huevo entero frito - TC | O11: 99.5 | P11: =(O11*M11)/I11 -> 199 | Q11: 6.75 | R11: =(Q11*M11)/I11 -> 13.5 | S11: 0.7 | T11: =(S11*M11)/I11 -> 1.4 | U11: 7.5 | V11: =(U11*M11)/I11 -> 15 | W11: 0 | X11: =(W11*M11)/I11 -> 0 | Y11: 27.5 | Z11: =(Y11*M11)/I11 -> 55 | AA11: 0.8 | AB11: =(AA11*M11)/I11 -> 1.6 | AC11: 176.5 | AD11: =(AC11*M11)/I11 -> 353
A12: 1 | B12: Medellín | C12: 19 - 30 | D12: Almuerzo | E12: Verduras y hortalizas | F12: Lechuga | G12: 1 | H12: Hoja | I12: 100 | J12: 0.1 | L12: =IF(J12=0,(K12/G12),J12) -> 0.1 | M12: =I12*L12 -> 10 | N12: Lechuga Comun - TC | O12: 1.8 | P12: =(O12*M12)/I12 -> 0.18 | Q12: 0.13 | R12: =(Q12*M12)/I12 -> 0.013 | S12: 0.35 | T12: =(S12*M12)/I12 -> 0.035 | U12: 0.03 | V12: =(U12*M12)/I12 -> 0.003 | W12: 0.19 | X12: =(W12*M12)/I12 -> 0.019 | Y12: 0.68 | Z12: =(Y12*M12)/I12 -> 0.068 | AA12: 0.14 | AB12: =(AA12*M12)/I12 -> 0.014 | AC12: 0.8 | AD12: =(AC12*M12)/I12 -> 0.08
A13: 1 | B13: Medellín | C13: 19 - 30 | D13: Algo | E13: Frutas | F13: Mango | G13: 1 | H13: Unidad | I13: 112 | J13: 1 | L13: =IF(J13=0,(K13/G13),J13) -> 1 | M13: =I13*L13 -> 112 | O13: 81 | P13: =(O13*M13)/I13 -> 81 | Q13: 0.6 | R13: =(Q13*M13)/I13 -> 0.6 | S13: 19 | T13: =(S13*M13)/I13 -> 19 | U13: 0.3 | V13: =(U13*M13)/I13 -> 0.3 | W13: 2 | X13: =(W13*M13)/I13 -> 2 | Y13: 11 | Z13: =(Y13*M13)/I13 -> 11 | AA13: 0.1 | AB13: =(AA13*M13)/I13 -> 0.1 | AC13: 2 | AD13: =(AC13*M13)/I13 -> 2
A14: 1 | B14: Medellín | C14: 19 - 30 | D14: Desayuno | E14: Cereales, raíces, tubérculos y plátanos | F14: Pan integral | G14: 1 | H14: tajada mediana | I14: 32 | J14: 1 | L14: =IF(J14=0,(K14/G14),J14) -> 1 | M14: =I14*L14 -> 32 | O14: 84 | P14: =(O14*M14)/I14 -> 84 | Q14: 3.1 | R14: =(Q14*M14)/I14 -> 3.1 | S14: 14.8 | T14: =(S14*M14)/I14 -> 14.8 | U14: 1.3 | V14: =(U14*M14)/I14 -> 1.3 | W14: 2.2 | X14: =(W14*M14)/I14 -> 2.2 | Y14: 23 | Z14: =(Y14*M14)/I14 -> 23 | AA14: 1.1 | AB14: =(AA14*M14)/I14 -> 1.1 | AC14: 169 | AD14: =(AC14*M14)/I14 -> 169
A15: 1 | B15: Medellín | C15: 19 - 30 | D15: Comida | E15: Cereales, raíces, tubérculos y plátanos | F15: Pan integral | G15: 1 | H15: tajada mediana | I15: 65 | J15: 1 | L15: =IF(J15=0,(K15/G15),J15) -> 1 | M15: =I15*L15 -> 65 | O15: 84 | P15: =(O15*M15)/I15 -> 84 | Q15: 3.1 | R15: =(Q15*M15)/I15 -> 3.1 | S15: 14.8 | T15: =(S15*M15)/I15 -> 14.8 | U15: 1.3 | V15: =(U15*M15)/I15 -> 1.3 | W15: 2.2 | X15: =(W15*M15)/I15 -> 2.2 | Y15: 23 | Z15: =(Y15*M15)/I15 -> 23 | AA15: 1.1 | AB15: =(AA15*M15)/I15 -> 1.1 | AC15: 169 | AD15: =(AC15*M15)/I15 -> 169
A16: 1 | B16: Medellín | C16: 19 - 30 | D16: Comida | E16: Azúcares y dulces | F16: Panela molida | G16: 1 | H16: Cucharada | I16: 10 | J16: 1 | L16: =IF(J16=0,(K16/G16),J16) -> 1 | M16: =I16*L16 -> 10 | O16: 90 | P16: =(O16*M16)/I16 -> 90 | Q16: 0.1 | R16: =(Q16*M16)/I16 -> 0.1 | S16: 22.4 | T16: =(S16*M16)/I16 -> 22.4 | U16: 0 | V16: =(U16*M16)/I16 -> 0 | W16: 0 | X16: =(W16*M16)/I16 -> 0 | Y16: 21 | Z16: =(Y16*M16)/I16 -> 21 | AA16: 0.6 | AB16: =(AA16*M16)/I16 -> 0.6 | AC16: 10 | AD16: =(AC16*M16)/I16 -> 10
A17: 1 | B17: Medellín | C17: 19 - 30 | D17: Comida | E17: Cereales, raíces, tubérculos y plátanos | F17: Papa | G17: 2 | H17: Unidad | I17: 83 | J17: 2 | L17: =IF(J17=0,(K17/G17),J17) -> 2 | M17: =I17*L17 -> 166 | N17: Papa comun - LI | O17: 73 | P17: =(O17*M17)/I17 -> 146 | Q17: 1.4 | R17: =(Q17*M17)/I17 -> 2.8 | S17: 16.6 | T17: =(S17*M17)/I17 -> 33.2 | U17: 0.1 | V17: =(U17*M17)/I17 -> 0.2 | W17: 1.5 | X17: =(W17*M17)/I17 -> 3 | Y17: 7 | Z17: =(Y17*M17)/I17 -> 14 | AA17: 0.2 | AB17: =(AA17*M17)/I17 -> 0.4 | AC17: 4 | AD17: =(AC17*M17)/I17 -> 8
A18: 1 | B18: Medellín | C18: 19 - 30 | D18: Almuerzo | E18: Cereales, raíces, tubérculos y plátanos | F18: Papas criollas | G18: 5 | H18: Unidades | I18: 105 | J18: 1 | L18: =IF(J18=0,(K18/G18),J18) -> 1 | M18: =I18*L18 -> 105 | O18: 93 | P18: =(O18*M18)/I18 -> 93 | Q18: 2.7 | R18: =(Q18*M18)/I18 -> 2.7 | S18: 20.2 | T18: =(S18*M18)/I18 -> 20.2 | U18: 0.1 | V18: =(U18*M18)/I18 -> 0.1 | W18: 1.7 | X18: =(W18*M18)/I18 -> 1.7 | Y18: 8 | Z18: =(Y18*M18)/I18 -> 8 | AA18: 0.6 | AB18: =(AA18*M18)/I18 -> 0.6 | AC18: 6 | AD18: =(AC18*M18)/I18 -> 6
A19: 1 | B19: Medellín | C19: 19 - 30 | D19: Almuerzo | E19: Carnes | F19: Pechuga de pollo | G19: 1 | H19: Unidad | I19: 80 | J19: 1 | L19: =IF(J19=0,(K19/G19),J19) -> 1 | M19: =I19*L19 -> 80 | O19: 83 | P19: =(O19*M19)/I19 -> 83 | Q19: 18.5 | R19: =(Q19*M19)/I19 -> 18.5 | S19: 0 | T19: =(S19*M19)/I19 -> 0 | U19: 1 | V19: =(U19*M19)/I19 -> 1 | W19: 0 | X19: =(W19*M19)/I19 -> 0 | Y19: 9 | Z19: =(Y19*M19)/I19 -> 9 | AA19: 0.6 | AB19: =(AA19*M19)/I19 -> 0.6 | AC19: 52 | AD19: =(AC19*M19)/I19 -> 52
A20: 1 | B20: Medellín | C20: 19 - 30 | D20: Comida | E20: Hierbas, especias y condimentos | F20: Perejil | G20: 1 | H20: Rama | I20: 100 | J20: 0.01 | L20: =IF(J20=0,(K20/G20),J20) -> 0.01 | M20: =I20*L20 -> 1 | O20: 2.76 | P20: =(O20*M20)/I20 -> 0.0276 | Q20: 0.224 | R20: =(Q20*M20)/I20 -> 0.00224 | S20: 0.517 | T20: =(S20*M20)/I20 -> 0.00517 | U20: 0.044 | V20: =(U20*M20)/I20 -> 0.00044 | W20: 0.304 | X20: =(W20*M20)/I20 -> 0.00304 | Y20: 14.68 | Z20: =(Y20*M20)/I20 -> 0.1468 | AA20: 0.979 | AB20: =(AA20*M20)/I20 -> 0.00979 | AC20: 4.52 | AD20: =(AC20*M20)/I20 -> 0.0452
A21: 1 | B21: Medellín | C21: 19 - 30 | D21: Desayuno | E21: Sustitutos | F21: Quesito | G21: 1 | H21: Tajada | I21: 20 | J21: 1 | L21: =IF(J21=0,(K21/G21),J21) -> 1 | M21: =I21*L21 -> 20 | O21: 83 | P21: =(O21*M21)/I21 -> 83 | Q21: 6.5 | R21: =(Q21*M21)/I21 -> 6.5 | S21: 1.5 | T21: =(S21*M21)/I21 -> 1.5 | U21: 5.7 | V21: =(U21*M21)/I21 -> 5.7 | W21: 0 | X21: =(W21*M21)/I21 -> 0 | Y21: 207 | Z21: =(Y21*M21)/I21 -> 207 | AA21: 0.2 | AB21: =(AA21*M21)/I21 -> 0.2 | AC21: 112 | AD21: =(AC21*M21)/I21 -> 112
A22: 1 | B22: Medellín | C22: 19 - 30 | D22: Almuerzo | E22: Verduras y hortalizas | F22: Tomates cherry | G22: 8 | H22: Unidades | I22: 60 | J22: 0.5 | L22: =IF(J22=0,(K22/G22),J22) -> 0.5 | M22: =I22*L22 -> 30 | P22: =(O22*M22)/I22 -> 0 | R22: =(Q22*M22)/I22 -> 0 | T22: =(S22*M22)/I22 -> 0 | V22: =(U22*M22)/I22 -> 0 | X22: =(W22*M22)/I22 -> 0 | Z22: =(Y22*M22)/I22 -> 0 | AB22: =(AA22*M22)/I22 -> 0 | AD22: =(AC22*M22)/I22 -> 0
A23: 1 | B23: Medellín | C23: 19 - 30 | D23: Algo | E23: Lacteos | F23: Yogur griego (con azucar) | G23: 1 | H23: Unidad | I23: 200 | J23: 1 | L23: =IF(J23=0,(K23/G23),J23) -> 1 | M23: =I23*L23 -> 200 | P23: =(O23*M23)/I23 -> 0 | R23: =(Q23*M23)/I23 -> 0 | T23: =(S23*M23)/I23 -> 0 | V23: =(U23*M23)/I23 -> 0 | X23: =(W23*M23)/I23 -> 0 | Z23: =(Y23*M23)/I23 -> 0 | AB23: =(AA23*M23)/I23 -> 0 | AD23: =(AC23*M23)/I23 -> 0
A24: 1 | B24: Medellín | C24: 19 - 30 | D24: Almuerzo | E24: Verduras y hortalizas | F24: Zanahoria | G24: 1 | H24: Unidad | I24: 58 | J24: 3 | L24: =IF(J24=0,(K24/G24),J24) -> 3 | M24: =I24*L24 -> 174 | O24: 27 | P24: =(O24*M24)/I24 -> 81 | Q24: 0.6 | R24: =(Q24*M24)/I24 -> 1.8 | S24: 5.9 | T24: =(S24*M24)/I24 -> 17.7 | U24: 0.1 | V24: =(U24*M24)/I24 -> 0.3 | W24: 1.7 | X24: =(W24*M24)/I24 -> 5.1 | Y24: 16 | Z24: =(Y24*M24)/I24 -> 48 | AA24: 0.3 | AB24: =(AA24*M24)/I24 -> 0.9 | AC24: 20 | AD24: =(AC24*M24)/I24 -> 60
A25: 1 | B25: Medellín | C25: 19 - 30 | D25: Comida | E25: Hierbas, especias y condimentos | F25: Zumo de Limón | G25: 1 | H25: Unidad | I25: 100 | J25: 0.1 | L25: =IF(J25=0,(K25/G25),J25) -> 0.1 | M25: =I25*L25 -> 10 | P25: =(O25*M25)/I25 -> 0 | R25: =(Q25*M25)/I25 -> 0 | T25: =(S25*M25)/I25 -> 0 | V25: =(U25*M25)/I25 -> 0 | X25: =(W25*M25)/I25 -> 0 | Z25: =(Y25*M25)/I25 -> 0 | AB25: =(AA25*M25)/I25 -> 0 | AD25: =(AC25*M25)/I25 -> 0
A26: 2 | B26: Medellin | C26: 31 - 50 | D26: Almuerzo | E26: Grasas | F26: Aguacate | G26: =1/8 -> 0.125 | H26: unidad mediana | I26: 30 | J26: 1 | L26: =IF(J26=0,(K26/G26),J26) -> 1 | M26: =I26*L26 -> 30 | O26: 53 | P26: =(O26*M26)/I26 -> 53 | Q26: 0.6 | R26: =(Q26*M26)/I26 -> 0.6 | S26: 2.2 | T26: =(S26*M26)/I26 -> 2.2 | U26: 4.6 | V26: =(U26*M26)/I26 -> 4.6 | W26: 1.5 | X26: =(W26*M26)/I26 -> 1.5 | Y26: 3 | Z26: =(Y26*M26)/I26 -> 3 | AA26: 0.3 | AB26: =(AA26*M26)/I26 -> 0.3 | AC26: 3 | AD26: =(AC26*M26)/I26 -> 3
A27: 2 | B27: Medellin | C27: 31 - 50 | D27: Desayuno | E27: Cereales, raíces, tubérculos y plátanos | F27: Arepa | G27: 1 | H27: Unidad grande | I27: 52 | J27: 1 | L27: =IF(J27=0,(K27/G27),J27) -> 1 | M27: =I27*L27 -> 52 | N27: Arepa delgada de maíz blanco trillado - LI | O27: 102 | P27: =(O27*M27)/I27 -> 102 | Q27: 2.1 | R27: =(Q27*M27)/I27 -> 2.1 | S27: 22.5 | T27: =(S27*M27)/I27 -> 22.5 | U27: 0.3 | V27: =(U27*M27)/I27 -> 0.3 | W27: 0.3 | X27: =(W27*M27)/I27 -> 0.3 | Y27: 2 | Z27: =(Y27*M27)/I27 -> 2 | AA27: 0.4 | AB27: =(AA27*M27)/I27 -> 0.4 | AC27: 1 | AD27: =(AC27*M27)/I27 -> 1
A28: 2 | B28: Medellin | C28: 31 - 50 | D28: Almuerzo | E28: Cereales, raíces, tubérculos y plátanos | F28: Arroz | G28: 6 | H28: Cucharadas soperas | I28: 80 | J28: 1 | L28: =IF(J28=0,(K28/G28),J28) -> 1 | M28: =I28*L28 -> 80 | N28: Arroz blanco cocido - LI | O28: 101 | P28: =(O28*M28)/I28 -> 101 | Q28: 1.9 | R28: =(Q28*M28)/I28 -> 1.9 | S28: 22.9 | T28: =(S28*M28)/I28 -> 22.9 | U28: 0.2 | V28: =(U28*M28)/I28 -> 0.2 | W28: 0.2 | X28: =(W28*M28)/I28 -> 0.2 | Y28: 2 | Z28: =(Y28*M28)/I28 -> 2 | AA28: 0.2 | AB28: =(AA28*M28)/I28 -> 0.2 | AC28: 0 | AD28: =(AC28*M28)/I28 -> 0
A29: 2 | B29: Medellin | C29: 31 - 50 | D29: Desayuno | E29: Sustitutos | F29: Cuajada | G29: 1 | H29: Tajada pequeña semi gruesa | I29: 20 | J29: 1 | L29: =IF(J29=0,(K29/G29),J29) -> 1 | M29: =I29*L29 -> 20 | O29: 77 | P29: =(O29*M29)/I29 -> 77 | Q29: 4.7 | R29: =(Q29*M29)/I29 -> 4.7 | S29: 1.8 | T29: =(S29*M29)/I29 -> 1.8 | U29: 5.7 | V29: =(U29*M29)/I29 -> 5.7 | W29: 0 | X29: =(W29*M29)/I29 -> 0 | Y29: 147 | Z29: =(Y29*M29)/I29 -> 147 | AA29: 0.5 | AB29: =(AA29*M29)/I29 -> 0.5 | AC29: 112 | AD29: =(AC29*M29)/I29 -> 112
A30: 2 | B30: Medellin | C30: 31 - 50 | D30: Almuerzo | E30: Verduras y hortalizas | F30: Ensalada | G30: 1 | H30: Taza | I30: 100 | J30: 0.5 | L30: =IF(J30=0,(K30/G30),J30) -> 0.5 | M30: =I30*L30 -> 50 | P30: =(O30*M30)/I30 -> 0 | R30: =(Q30*M30)/I30 -> 0 | T30: =(S30*M30)/I30 -> 0 | V30: =(U30*M30)/I30 -> 0 | X30: =(W30*M30)/I30 -> 0 | Z30: =(Y30*M30)/I30 -> 0 | AB30: =(AA30*M30)/I30 -> 0 | AD30: =(AC30*M30)/I30 -> 0
A31: 2 | B31: Medellin | C31: 31 - 50 | D31: Comida | E31: Verduras y hortalizas | F31: Ensalada | G31: 1 | H31: Taza | I31: 100 | J31: 0.5 | L31: =IF(J31=0,(K31/G31),J31) -> 0.5 | M31: =I31*L31 -> 50 | P31: =(O31*M31)/I31 -> 0 | R31: =(Q31*M31)/I31 -> 0 | T31: =(S31*M31)/I31 -> 0 | V31: =(U31*M31)/I31 -> 0 | X31: =(W31*M31)/I31 -> 0 | Z31: =(Y31*M31)/I31 -> 0 | AB31: =(AA31*M31)/I31 -> 0 | AD31: =(AC31*M31)/I31 -> 0
A32: 2 | B32: Medellin | C32: 31 - 50 | D32: Media Mañana | E32: Frutas | F32: Ensalada de fruta (promedio - manzana verde, melón, papaya, piña) | G32: 1 | H32: Vaso pequeño | I32: 100 | J32: 1 | L32: =IF(J32=0,(K32/G32),J32) -> 1 | M32: =I32*L32 -> 100 | N32: Promedio de grupo frutas | O32: 59 | P32: =(O32*M32)/I32 -> 59 | Q32: 1 | R32: =(Q32*M32)/I32 -> 1 | S32: 13.3 | T32: =(S32*M32)/I32 -> 13.3 | U32: 0.3 | V32: =(U32*M32)/I32 -> 0.3 | W32: 2.6 | X32: =(W32*M32)/I32 -> 2.6 | Y32: 21 | Z32: =(Y32*M32)/I32 -> 21 | AA32: 0.5 | AB32: =(AA32*M32)/I32 -> 0.5 | AC32: 4 | AD32: =(AC32*M32)/I32 -> 4
A33: 2 | B33: Medellin | C33: 31 - 50 | D33: Desayuno | E33: Frutas | F33: Fresa | G33: 9 | H33: unidades | I33: 161 | K33: 3 | L33: =IF(J33=0,(K33/G33),J33) -> 0.33333333 | M33: =I33*L33 -> 53.666667 | O33: 55 | P33: =(O33*M33)/I33 -> 18.333333 | Q33: 1.3 | R33: =(Q33*M33)/I33 -> 0.43333333 | S33: 11.1 | T33: =(S33*M33)/I33 -> 3.7 | U33: 0.6 | V33: =(U33*M33)/I33 -> 0.2 | W33: 3.7 | X33: =(W33*M33)/I33 -> 1.2333333 | Y33: 45 | Z33: =(Y33*M33)/I33 -> 15 | AA33: 1.3 | AB33: =(AA33*M33)/I33 -> 0.43333333 | AC33: 2 | AD33: =(AC33*M33)/I33 -> 0.66666667
A34: 2 | B34: Medellin | C34: 31 - 50 | D34: Media Mañana | E34: Nueces | F34: Frutos secos | G34: 1 | H34: puño | I34: 30 | J34: 2 | L34: =IF(J34=0,(K34/G34),J34) -> 2 | M34: =I34*L34 -> 60 | N34: Almendras | O34: 56 | P34: =(O34*M34)/I34 -> 112 | Q34: 1.5 | R34: =(Q34*M34)/I34 -> 3 | S34: 2.2 | T34: =(S34*M34)/I34 -> 4.4 | U34: 4.6 | V34: =(U34*M34)/I34 -> 9.2 | W34: 1.2 | X34: =(W34*M34)/I34 -> 2.4 | Y34: 25 | Z34: =(Y34*M34)/I34 -> 50 | AA34: 0.3 | AB34: =(AA34*M34)/I34 -> 0.6 | AC34: 1 | AD34: =(AC34*M34)/I34 -> 2
A35: 2 | B35: Medellin | C35: 31 - 50 | D35: Algo | E35: Azúcares y dulces | F35: Gelatina (con azucar) | G35: 1 | H35: pocillo chocolatero | I35: 160 | J35: 1 | L35: =IF(J35=0,(K35/G35),J35) -> 1 | M35: =I35*L35 -> 160 | O35: 97 | P35: =(O35*M35)/I35 -> 97 | Q35: 1.9 | R35: =(Q35*M35)/I35 -> 1.9 | S35: 22.4 | T35: =(S35*M35)/I35 -> 22.4 | U35: 0 | V35: =(U35*M35)/I35 -> 0 | W35: 0 | X35: =(W35*M35)/I35 -> 0 | Y35: 3 | Z35: =(Y35*M35)/I35 -> 3 | AA35: 0 | AB35: =(AA35*M35)/I35 -> 0 | AC35: 67 | AD35: =(AC35*M35)/I35 -> 67 | AE35: la información no sale en fitia
A36: 2 | B36: Medellin | C36: 31 - 50 | D36: Almuerzo | E36: Frutas | F36: Guayaba (Jugo, 1 guayaba) | G36: 1 | H36: unidad mediana | I36: 105 | J36: 1 | L36: =IF(J36=0,(K36/G36),J36) -> 1 | M36: =I36*L36 -> 105 | N36: Guayaba criolla | O36: 59 | P36: =(O36*M36)/I36 -> 59 | Q36: 0.8 | R36: =(Q36*M36)/I36 -> 0.8 | S36: 12.5 | T36: =(S36*M36)/I36 -> 12.5 | U36: 0.6 | V36: =(U36*M36)/I36 -> 0.6 | W36: 5.7 | X36: =(W36*M36)/I36 -> 5.7 | Y36: 21 | Z36: =(Y36*M36)/I36 -> 21 | AA36: 0.3 | AB36: =(AA36*M36)/I36 -> 0.3 | AC36: 3 | AD36: =(AC36*M36)/I36 -> 3
A37: 2 | B37: Medellin | C37: 31 - 50 | D37: Desayuno | E37: Sustitutos | F37: Huevos | G37: 1 | H37: Unidad | I37: 50 | J37: 2 | L37: =IF(J37=0,(K37/G37),J37) -> 2 | M37: =I37*L37 -> 100 | N37: Huevo entero frito - TC | O37: 99.5 | P37: =(O37*M37)/I37 -> 199 | Q37: 6.75 | R37: =(Q37*M37)/I37 -> 13.5 | S37: 0.7 | T37: =(S37*M37)/I37 -> 1.4 | U37: 7.5 | V37: =(U37*M37)/I37 -> 15 | W37: 0 | X37: =(W37*M37)/I37 -> 0 | Y37: 27.5 | Z37: =(Y37*M37)/I37 -> 55 | AA37: 0.8 | AB37: =(AA37*M37)/I37 -> 1.6 | AC37: 176.5 | AD37: =(AC37*M37)/I37 -> 353
A38: 2 | B38: Medellin | C38: 31 - 50 | D38: Almuerzo | E38: Sustitutos | F38: Huevos | G38: 1 | H38: Unidad | I38: 50 | J38: 1 | L38: =IF(J38=0,(K38/G38),J38) -> 1 | M38: =I38*L38 -> 50 | N38: Huevo entero frito - TC | O38: 99.5 | P38: =(O38*M38)/I38 -> 99.5 | Q38: 6.75 | R38: =(Q38*M38)/I38 -> 6.75 | S38: 0.7 | T38: =(S38*M38)/I38 -> 0.7 | U38: 7.5 | V38: =(U38*M38)/I38 -> 7.5 | W38: 0 | X38: =(W38*M38)/I38 -> 0 | Y38: 27.5 | Z38: =(Y38*M38)/I38 -> 27.5 | AA38: 0.8 | AB38: =(AA38*M38)/I38 -> 0.8 | AC38: 176.5 | AD38: =(AC38*M38)/I38 -> 176.5
A39: 2 | B39: Medellin | C39: 31 - 50 | D39: Algo | E39: Bebidas no alcohólicas | F39: Infusion de frutas | N39: Ver notas | O39: 0 | P39: =(O39*M39)/I39 -> #DIV/0! | Q39: 0 | R39: =(Q39*M39)/I39 -> #DIV/0! | S39: 0 | T39: =(S39*M39)/I39 -> #DIV/0! | U39: 0 | V39: =(U39*M39)/I39 -> #DIV/0! | W39: 0 | X39: =(W39*M39)/I39 -> #DIV/0! | Y39: 0 | Z39: =(Y39*M39)/I39 -> #DIV/0! | AA39: 0 | AB39: =(AA39*M39)/I39 -> #DIV/0! | AC39: 0 | AD39: =(AC39*M39)/I39 -> #DIV/0!
A40: 2 | B40: Medellin | C40: 31 - 50 | D40: Desayuno | E40: Bebidas no alcohólicas | F40: Jugo de naranja | G40: 1 | H40: Vaso pequeño | I40: 200 | J40: 1 | L40: =IF(J40=0,(K40/G40),J40) -> 1 | M40: =I40*L40 -> 200 | N40: Jugo de naranja - LI | O40: 92 | P40: =(O40*M40)/I40 -> 92 | Q40: 1.4 | R40: =(Q40*M40)/I40 -> 1.4 | S40: 20.8 | T40: =(S40*M40)/I40 -> 20.8 | U40: 0.4 | V40: =(U40*M40)/I40 -> 0.4 | W40: 0.4 | X40: =(W40*M40)/I40 -> 0.4 | Y40: 22 | Z40: =(Y40*M40)/I40 -> 22 | AA40: 0.4 | AB40: =(AA40*M40)/I40 -> 0.4 | AC40: 2 | AD40: =(AC40*M40)/I40 -> 2
...

Sheet GABAS
B1: KCAL | G1: PROT | K1: GT | O1: CHO | S1: FD GABA Masc | W1: CA | Z1: FE
B2: GABA | E2: ESTUDIO | F2: COMPARACION | G2: GABA | I2: ESTUDIO | J2: COMPARACION | K2: GABA | M2: ESTUDIO | N2: COMPARACION | O2: GABA | Q2: ESTUDIO | R2: COMPARACION | S2: GABA | U2: ESTUDIO | V2: COMPARACION | W2: GABA | X2: ESTUDIO | Y2: COMPARACION | Z2: GABA | AB2: ESTUDIO | AC2: COMPARACION
A3: Grupo | B3: Kcal GABA Masc | C3: Kcal GABA Fem | D3: Kcal GABA Prom | E3: Kcal Percibida | G3: Prot GABA Masc | H3: Prot GABA Fem | I3: Prot Percibida | K3: GT GABA Mac | L3: GT GABA Fem | M3: GT Percibida | O3: CHO GABA Masc | P3: CHO GABA Fem | Q3: CHO Percibida | S3: FD GABA Masc | T3: FD GABA Fem | U3: FD Percibida | W3: CA GABA | X3: CA Percibida | Z3: FE BAGA Masc | AA3: FE GABA Fem | AB3: FE Percibida
A4: 19 - 30 | B4: 2650 | C4: 2100 | E4: =AVERAGE(B10,B13,B16) -> #DIV/0! | F4: =D4-E4 -> #DIV/0! | G4: 99.5 | H4: 78.7 | I4: =AVERAGE(C10,C13,C16) -> #DIV/0! | K4: 88.3 | L4: 70 | M4: =AVERAGE(D10,D13,D16) -> #DIV/0! | O4: 364.5 | P4: 288.7 | Q4: =AVERAGE(E10,E13,E16) -> #DIV/0! | S4: 37 | T4: 29 | U4: =AVERAGE(F10,F13,F16) -> #DIV/0! | W4: 1000 | X4: =AVERAGE(G10,G13,G16) -> #DIV/0! | Z4: 13 | AA4: 27 | AB4: =AVERAGE(H10,H13,H16) -> #DIV/0!
A5: 31 - 59 | B5: 2650 | C5: 2100 | E5: =AVERAGE(B11,B14,B17) -> #DIV/0! | F5: =D5-E5 -> #DIV/0! | G5: 99.5 | H5: 78.7 | I5: =AVERAGE(C11,C14,C17) -> #DIV/0! | K5: 88.3 | L5: 70 | M5: =AVERAGE(D11,D14,D17) -> #DIV/0! | O5: 364.5 | P5: 288.7 | Q5: =AVERAGE(E11,E14,E17) -> #DIV/0! | S5: 37 | T5: 29 | U5: =AVERAGE(F11,F14,F17) -> #DIV/0! | W5: 1000 | X5: =AVERAGE(G11,G14,G17) -> #DIV/0! | Z5: 13 | AA5: 27 | AB5: =AVERAGE(H11,H14,H17) -> #DIV/0!
A6: 60+ | B6: 2172 | C6: 1895 | D6: 2000 | E6: =AVERAGE(B12,B15,B18) -> 1669.5878 | F6: =D6-E6 -> 330.41222 | G6: 75 | H6: 75 | I6: =AVERAGE(C12,C15,C18) -> 76.868444 | K6: 66.7 | L6: 66.7 | M6: =AVERAGE(D12,D15,D18) -> 44.027667 | O6: 275 | P6: 275 | Q6: =AVERAGE(E12,E15,E18) -> 241.96167 | S6: 28 | T6: 28 | U6: =AVERAGE(F12,F15,F18) -> 31.717444 | W6: 1150 | X6: =AVERAGE(G12,G15,G18) -> 661.52267 | Z6: 13 | AA6: 13 | AB6: =AVERAGE(H12,H15,H18) -> 10.185778
A9: ID | B9: kcal | C9: prot | D9: gt | E9: cho | F9: fd | G9: ca | H9: fe
A10: 1 | B10: =SUM(Gramaje!P2:P25) -> 1477.7276 | C10: =SUM(Gramaje!R2:R25) -> 77.16764 | D10: =SUM(Gramaje!V2:V25) -> 40.10404 | E10: =SUM(Gramaje!T2:T25) -> 200.29277 | F10: =SUM(Gramaje!X2:X25) -> 26.07434 | G10: =+SUM(Gramaje!Z2:Z25) -> 545.8128 | H10: =SUM(Gramaje!AB2:AB24) -> 11.67579
A11: =A10+1 -> 2 | B11: =SUM(Gramaje!P26:P45) -> #DIV/0! | C11: =SUM(Gramaje!R26:R45) -> #DIV/0! | D11: =SUM(Gramaje!V26:V45) -> #DIV/0! | E11: =SUM(Gramaje!T26:T45) -> #DIV/0! | F11: =SUM(Gramaje!X26:X45) -> #DIV/0! | G11: =SUM(Gramaje!Z26:Z45) -> #DIV/0! | H11: =SUM(Gramaje!AB26:AB45) -> #DIV/0!
A12: =A11+1 -> 3 | B12: =SUM(Gramaje!P46:P77) -> 2070.0133 | C12: =SUM(Gramaje!R46:R77) -> 98.946333 | D12: =SUM(Gramaje!V46:V77) -> 57.853 | E12: =SUM(Gramaje!T46:T77) -> 286.835 | F12: =SUM(Gramaje!X46:X77) -> 56.802333 | G12: =SUM(Gramaje!Z46:Z77) -> 393.068 | H12: =SUM(Gramaje!AB46:AB77) -> 15.997333
A13: =A12+1 -> 4 | B13: =SUM(Gramaje!P78:P101) -> #DIV/0! | C13: =SUM(Gramaje!R78:R101) -> #DIV/0! | D13: =SUM(Gramaje!V78:V101) -> #DIV/0! | E13: =SUM(Gramaje!T78:T101) -> #DIV/0! | F13: =SUM(Gramaje!X78:X101) -> #DIV/0! | G13: =SUM(Gramaje!Z78:Z101) -> #DIV/0! | H13: =SUM(Gramaje!AB78:AB101) -> #DIV/0!
A14: =A13+1 -> 5 | B14: =SUM(Gramaje!P102:P145) -> #DIV/0! | C14: =SUM(Gramaje!R102:R145) -> #DIV/0! | D14: =SUM(Gramaje!V102:V145) -> #DIV/0! | E14: =SUM(Gramaje!T102:T145) -> #DIV/0! | F14: =SUM(Gramaje!X102:X145) -> #DIV/0! | G14: =SUM(Gramaje!Z102:Z145) -> #DIV/0! | H14: =SUM(Gramaje!AB102:AB145) -> #DIV/0!
A15: =A14+1 -> 6 | B15: =SUM(Gramaje!P146:P164) -> 1135.5 | C15: =SUM(Gramaje!R146:R164) -> 78.8 | D15: =SUM(Gramaje!V146:V164) -> 31.6 | E15: =SUM(Gramaje!T146:T164) -> 136.35 | F15: =SUM(Gramaje!X146:X164) -> 13.65 | G15: =SUM(Gramaje!Z146:Z164) -> 333 | H15: =SUM(Gramaje!AB146:AB164) -> 5.9
A16: =A15+1 -> 7 | B16: =SUM(Gramaje!P165:P196) -> #DIV/0! | C16: =SUM(Gramaje!R165:R196) -> #DIV/0! | D16: =SUM(Gramaje!V165:V196) -> #DIV/0! | E16: =SUM(Gramaje!T165:T196) -> #DIV/0! | F16: =SUM(Gramaje!X165:X196) -> #DIV/0! | G16: =SUM(Gramaje!Z165:Z196) -> #DIV/0! | H16: =SUM(Gramaje!AB165:AB196) -> #DIV/0!
A17: =A16+1 -> 8 | B17: =SUM(Gramaje!P197:P218) -> #DIV/0! | C17: =SUM(Gramaje!R197:R218) -> #DIV/0! | D17: =SUM(Gramaje!V197:V218) -> #DIV/0! | E17: =SUM(Gramaje!T197:T218) -> #DIV/0! | F17: =SUM(Gramaje!X197:X218) -> #DIV/0! | G17: =SUM(Gramaje!Z197:Z218) -> #DIV/0! | H17: =SUM(Gramaje!AB197:AB218) -> #DIV/0!
A18: =A17+1 -> 9 | B18: =SUM(Gramaje!P219:P243) -> 1803.25 | C18: =SUM(Gramaje!R219:R243) -> 52.859 | D18: =SUM(Gramaje!V219:V243) -> 42.63 | E18: =SUM(Gramaje!T219:T243) -> 302.7 | F18: =SUM(Gramaje!X219:X243) -> 24.7 | G18: =SUM(Gramaje!Z219:Z243) -> 1258.5 | H18: =SUM(Gramaje!AB219:AB243) -> 8.66

Sheet GABAS_Referencias
A1: Grupo de alimentos / grupo de edad | B1: Hombres (18-59 años) | C1: Mujeres (18-59 años) | D1: Hombres y mujeres (>60 años) | E1: Promedio adultos y adulto mayor
A2: Cereales, tubérculos, raíces y plátanos | B2: 8 | C2: 6 | D2: 5.5 | E2: =AVERAGE(B2:D2) -> 6.5
A3: Verduras y frutas | B3: 5 | C3: 4 | D3: 3.5 | E3: =AVERAGE(B3:D3) -> 4.1666667
A4: Leche y productos lácteos | B4: 5 | C4: 3.5 | D4: 3.5 | E4: =AVERAGE(B4:D4) -> 4
A5: Carnes, huevos y leguminosas secas | B5: 7.5 | C5: 6.5 | D5: 6 | E5: =AVERAGE(B5:D5) -> 6.6666667
A6: Grasas | B6: 5 | C6: 4 | D6: 5 | E6: =AVERAGE(B6:D6) -> 4.6666667
A7: Azúcares | B7: 3 | C7: 3 | D7: 3 | E7: =AVERAGE(B7:D7) -> 3

Sheet RIEN
A1: Grupo | B1: Calorias_ref | C1: Proteina_EAR | D1: Proteina_RDA | E1: CHO_EAR | F1: CHO_RDA | G1: Grasas_AI_min | H1: Grasas_AI_max | I1: Fribra_AI | J1: Calcio_EAR | K1: Calcio_RDA | L1: Hierro_EAR | M1: Hierro_RDA | N1: Sodio_AI
A2: 19 a 30 años | B2: 2200 | C2: =0.92*70 -> 64.4 | D2: =1.11*70 -> 77.7 | E2: 100 | F2: 130 | G2: 20 | H2: 35 | I2: =AVERAGE(38,25) -> 31.5 | J2: 800 | K2: 1000 | L2: =AVERAGE(9,11.7) -> 10.35 | M2: =AVERAGE(13,27) -> 20 | N2: 1500
A3: 31 a 50 años | B3: 2200 | C3: =0.92*70 -> 64.4 | D3: =1.11*70 -> 77.7 | E3: 100 | F3: 130 | G3: 20 | H3: 35 | I3: =AVERAGE(38,25) -> 31.5 | J3: 800 | K3: 1000 | L3: =AVERAGE(9,11.7) -> 10.35 | M3: =AVERAGE(13,27) -> 20 | N3: 1500
A4: 51 a 70 años | B4: 2200 | C4: =0.92*70 -> 64.4 | D4: =1.11*70 -> 77.7 | E4: 100 | F4: 130 | G4: 20 | H4: 35 | I4: =AVERAGE(30,21) -> 25.5 | J4: 800 | K4: 1000 | L4: =AVERAGE(9,7.5) -> 8.25 | M4: =AVERAGE(13,12) -> 12.5 | N4: 1300
A8: Aclaraciones
A9: Calorias_ref | B9: Se toma los datos de referencia de un adulto de 70kg, según los estándares de la Población Colombiana
A10: Proteina | B10: El valor está en g/kg/dia se multiplica por 70kg para ponerlo al promedio colombiano
A11: CHO | B11: Están en g/dia no tenemos que hacer nada
A12: Grasas
A13: Fribra | B13: Promedio Hombre Mujeres
A14: Calcio | B14: Los datos de hombre y mujeres son los mismos
A15: Hierro
A16: Sodio | B16: NO está EAR
A18: AI | B18: lngesta Adecuada (Al - Adequate Intake): nivel de ingesta promedio recomendado sobre la base de estimaciones de ingesta observada de un nutriente o ingesta determinada por aproximaciones experimentales o a partir de estimaciones de la ingesta de nutrientes para un grupo o grupos de personas aparentemente saludables, en quienes se asume que ésta es adecuada, según criterios de adecuación establecidos para cada nutriente. La Al se establece en lugar del RDA cuando no hay suficiente evidencia científica para establecer el EAR y así calcular el RDA.
A19: RDA | B19: Aporte Dietético Recomendado (RDA - Recommended Dieta°, Allowance): es una estimación del nivel de ingesta diaria promedio de un nutriente, que es suficiente para cubrir las necesidades de casi todos los individuos saludables de un grupo particular (97 - 98%) por período de vida, condición fisiológica y género.
A20: EAR | B20: Requerimiento Promedio Estimado (EAR - Estimated Average Requirement): nivel de ingesta promedio diario estimado que cubre el requerimiento de la mitad de los individuos saludables (50%) de un grupo de edad, por periodo de la vida, estado fisiológico y género específicos.

Sheet equiv_table_GABAS
A1: G_Alimento | B1: G_Alimento_GABA
A2: Azúcares y dulces | B2: Azúcares
A3: Bebidas no alcohólicas | B3: No hay
A4: Carnes | B4: Carnes, huevos y leguminosas secas
A5: Cereales, raíces, tubérculos y plátanos | B5: Cereales, tubérculos, raíces y plátanos
A6: Frutas | B6: Verduras y frutas
A7: Grasas | B7: Grasas
A8: Hierbas, especias y condimentos | B8: No hay
A9: Lacteos | B9: Leche y productos lácteos
A10: Leguminosas Cocidas | B10: Carnes, huevos y leguminosas secas
A11: Nueces | B11: Grasas
A12: Sustitutos | B12: Carnes, huevos y leguminosas secas
A13: Verduras y hortalizas | B13: Verduras y frutas

Sheet Puntaje Dietas
A1: ID | B1: Puntaje
A2: 1 | B2: 3.8
A3: 1 | B3: 3.5
A4: 1 | B4: 4
A5: 1 | B5: 3.5
A6: 1 | B6: 3
A7: 2 | B7: 3
A8: 2 | B8: 3
A9: 2 | B9: 4.5
A10: 2 | B10: 4
A11: 3 | B11: 3.5
A12: 3 | B12: 4
A13: 3 | B13: 2.8
... A21: 5 | B21: 3.5
A22: 6 | B22: 3 | C22: faltan 3 puntajes de ID 6
A23: 6 | B23: 4
A24: 6 | B24: 3
A25: 7 | B25: 4
A26: 7 | B26: 2.8
A27: 7 | B27: 3
A28: 7 | B28: 2
A29: 7 | B29: 2
A30: 7 | B30: 3
A31: 8 | B31: 2
A32: 8 | B32: 2
A33: 8 | B33: 4
A34: 8 | B34: 2
... A38: 9 | B38: 4

Sheet Taller EAFIT
A1: Grupo 1 | G1: Rango de edad: 19 a 30 | M1: Grupo 2 | S1: Rango de edad: 31-50 años | Z1: Grupo 3 | AF1: Rango de edad: +50
A3: Plato | B3: Grupo | C3: Alimento | D3: Unidad de medida por porción | E3: Medida casera | F3: Gramos porción | G3: Porción elegida | H3: Unidades | I3: Porción final | J3: Cantidad total gramos | K3: Observaciones | N3: Grupo | O3: Alimento | P3: Unidad de medida | Q3: Medida casera | R3: Gramos porción | S3: Porción elegida | T3: Unidades | U3: Porción final | V3: Cantidad total gramos | W3: Observaciones | AA3: Grupo | AB3: Alimento | AC3: Unidad de medida | AD3: Medida casera | AE3: Gramos porción | AF3: Porción elegida | AG3: Unidades | AH3: Porción final | AI3: Cantidad total gramos | AJ3: Observaciones
A4: Desayuno | B4: Frutas | C4: Fresa | D4: 9 | E4: unidades | F4: 161 | G4: 0.5 | I4: =IF(G4=0,(H4/D4),G4) -> 0.5 | J4: =I4*F4 -> 80.5 | M4: Desayuno | N4: Frutas | O4: Fresa | P4: 9 | Q4: unidades | R4: 161 | T4: 3 | U4: =IF(S4=0,(T4/P4),S4) -> 0.33333333 | V4: =R4*U4 -> 53.666667 | Z4: Desayuno | AB4: Agua | AC4: 1 | AD4: Vaso de tinto | AE4: 150 | AF4: 1 | AH4: =IF(AF4=0,(AG4/AC4),AF4) -> 1 | AI4: =AE4*AH4 -> 150
A5: Desayuno | B5: Grasas | C5: Tajada de queso | D5: 1 | E5: Tajada | F5: 20 | G5: 1 | I5: =IF(G5=0,(H5/D5),G5) -> 1 | J5: =F5*I5 -> 20 | O5: Arepa | P5: 1 | Q5: Unidad grande | R5: 52 | S5: 1 | U5: =IF(S5=0,(T5/P5),S5) -> 1 | V5: =R5*U5 -> 52 | AB5: Huevo cocido | AC5: 1 | AD5: unidad | AE5: 50 | AF5: 2 | AH5: =IF(AF5=0,(AG5/AC5),AF5) -> 2 | AI5: =AE5*AH5 -> 100
A6: Desayuno | B6: Leguminosas | C6: Banano | D6: 1 | E6: Unidad pequeña | F6: 65 | G6: 1 | I6: =IF(G6=0,(H6/D6),G6) -> 1 | J6: =F6*G6 -> 65 | O6: Huevos | P6: 1 | Q6: Unidad | R6: 50 | S6: 2 | U6: =IF(S6=0,(T6/P6),S6) -> 2 | V6: =R6*U6 -> 100 | AB6: Arepa | AC6: 1 | AD6: unidad grande | AE6: 52 | AF6: 1 | AH6: =IF(AF6=0,(AG6/AC6),AF6) -> 1 | AI6: =AE6*AH6 -> 52
A7: Desayuno | B7: Carnes | C7: Huevo | D7: 1 | E7: unidad | F7: 50 | G7: 2 | I7: =IF(G7=0,(H7/D7),G7) -> 2 | J7: =F7*I7 -> 100 | O7: Cuajada | P7: 1 | Q7: Tajada pequeña semi gruesa | R7: 20 | S7: 1 | U7: =IF(S7=0,(T7/P7),S7) -> 1 | V7: =R7*U7 -> 20 | Z7: Almuerzo | AB7: Agua | AC7: 1 | AD7: Vaso de tinto | AE7: 150 | AF7: 1 | AH7: =IF(AF7=0,(AG7/AC7),AF7) -> 1 | AI7: =AE7*AH7 -> 150
A8: Desayuno | C8: Pan integral | D8: 1 | E8: tajada mediana | F8: 32 | G8: 1 | I8: =IF(G8=0,(H8/D8),G8) -> 1 | J8: =F8*I8 -> 32 | O8: Jugo de naranja | P8: 1 | Q8: Vaso pequeño | R8: 200 | S8: 1 | U8: =IF(S8=0,(T8/P8),S8) -> 1 | V8: =R8*U8 -> 200 | AB8: Papa cocida | AC8: 1 | AD8: unidad mediana | AE8: 83 | AF8: 2 | AH8: =IF(AF8=0,(AG8/AC8),AF8) -> 2 | AI8: =AE8*AH8 -> 166
A9: Almuerzo | C9: Pechuga de pollo | D9: 1 | E9: Unidad | F9: 80 | G9: 1 | I9: =IF(G9=0,(H9/D9),G9) -> 1 | J9: =F9*I9 -> 80 | M9: Almuerzo | O9: Arroz | P9: 6 | Q9: Cucharadas soperas | R9: 80 | S9: 1 | U9: =IF(S9=0,(T9/P9),S9) -> 1 | V9: =R9*U9 -> 80 | AB9: Lentejas | AC9: 1 | AD9: cucharon colmado | AE9: 130 | AF9: 1 | AH9: =IF(AF9=0,(AG9/AC9),AF9) -> 1 | AI9: =AE9*AH9 -> 130
A10: Almuerzo | C10: Tomates cherry | E10: Unidades | G10: 4 | I10: =IF(G10=0,(H10/D10),G10) -> 4 | J10: =F10*I10 -> 0 | O10: Lentejas | P10: 1 | Q10: Cucharon colmado | R10: 130 | S10: 1 | U10: =IF(S10=0,(T10/P10),S10) -> 1 | V10: =R10*U10 -> 130 | AB10: Aguacate | AC10: =1/8 -> 0.125 | AD10: unidad mediana | AE10: 30 | AF10: 1 | AH10: =IF(AF10=0,(AG10/AC10),AF10) -> 1 | AI10: =AE10*AH10 -> 30
A11: Almuerzo | C11: Papas criollas | D11: 1 | E11: Unidades | F11: 105 | G11: 5 | I11: =IF(G11=0,(H11/D11),G11) -> 5 | J11: =F11*I11 -> 525 | O11: Huevos | P11: 1 | Q11: Unidad | R11: 50 | S11: 1 | U11: =IF(S11=0,(T11/P11),S11) -> 1 | V11: =R11*U11 -> 50 | AB11: Lechuga | AC11: 1 | AD11: hoja | AF11: 1 | AH11: =IF(AF11=0,(AG11/AC11),AF11) -> 1 | AI11: =AE11*AH11 -> 0 | AJ11: TC
A12: Almuerzo | C12: Lechuga | D12: 1 | E12: Hoja | G12: 2 | I12: =IF(G12=0,(H12/D12),G12) -> 2 | J12: =F12*I12 -> 0 | K12: TC | O12: Ensalada | Q12: T.C | S12: 1 | U12: =IF(S12=0,(T12/P12),S12) -> 1 | V12: =R12*U12 -> 0 | AB12: Tomate | AC12: 1 | AD12: unidad pequeña | AE12: 132 | AF12: 1 | AH12: =IF(AF12=0,(AG12/AC12),AF12) -> 1 | AI12: =AE12*AH12 -> 132
A13: Almuerzo | C13: Aguacate | D13: =1/8 -> 0.125 | E13: unidad mediana | F13: 30 | G13: 1 | I13: =IF(G13=0,(H13/D13),G13) -> 1 | J13: =F13*I13 -> 30 | O13: Pollo | P13: 1 | Q13: Unidad mediana | R13: 75 | S13: 1 | U13: =IF(S13=0,(T13/P13),S13) -> 1 | V13: =R13*U13 -> 75 | AB13: Zanahoria | AC13: 1 | AD13: unidad | AE13: 58 | AF13: 0.5 | AH13: =IF(AF13=0,(AG13/AC13),AF13) -> 0.5 | AI13: =AE13*AH13 -> 29
A14: Almuerzo | C14: Zanahoria | D14: 1 | E14: Unidad | F14: 58 | G14: 3 | I14: =IF(G14=0,(H14/D14),G14) -> 3 | J14: =F14*I14 -> 174 | O14: Jugo de guayaba | P14: 1 | Q14: Vaso mediano | U14: =IF(S14=0,(T14/P14),S14) -> 0 | V14: =R14*U14 -> 0 | AB14: Pollo | AC14: 1 | AD14: unidad | AE14: 80 | AF14: 1 | AH14: =IF(AF14=0,(AG14/AC14),AF14) -> 1 | AI14: =AE14*AH14 -> 80
A15: Almuerzo | C15: Cilantro | E15: Ramas | G15: 1 | I15: =IF(G15=0,(H15/D15),G15) -> 1 | J15: =F15*I15 -> 0 | O15: Aguacate | P15: =1/8 -> 0.125 | Q15: unidad mediana | R15: 30 | S15: 1 | U15: =IF(S15=0,(T15/P15),S15) -> 1 | V15: =R15*U15 -> 30 | Z15: Comida | AB15: Cebolla
A16: Comida | C16: Camarones | D16: 1 | E16: Porción | F16: 300 | G16: 1 | I16: =IF(G16=0,(H16/D16),G16) -> 1 | J16: =F16*I16 -> 300 | M16: Comida | O16: Pollo | P16: 1 | Q16: Unidad grande | R16: 80 | S16: 1 | U16: =IF(S16=0,(T16/P16),S16) -> 1 | V16: =R16*U16 -> 80 | AB16: Carne de cerdo | AC16: 1 | AD16: unidad | AE16: 100 | AF16: 1 | AH16: =IF(AF16=0,(AG16/AC16),AF16) -> 1 | AI16: =AE16*AH16 -> 100
A17: Comida | C17: Brócoli | D17: 1 | E17: Unidad | F17: 89 | G17: 1 | I17: =IF(G17=0,(H17/D17),G17) -> 1 | J17: =F17*I17 -> 89 | O17: Papa criolla | P17: 3 | Q17: Unidades | R17: 108 | S17: 1 | U17: =IF(S17=0,(T17/P17),S17) -> 1 | V17: =R17*U17 -> 108 | AB17: Zanahoria | AC17: 1 | AD17: unidad | AE17: 58 | AF17: 0.5 | AH17: =IF(AF17=0,(AG17/AC17),AF17) -> 0.5 | AI17: =AE17*AH17 -> 29
A18: Comida | C18: Pan integral | D18: 1 | E18: tajada mediana | F18: 65 | G18: 1 | I18: =IF(G18=0,(H18/D18),G18) -> 1 | J18: =F18*I18 -> 65 | O18: Ensalada | Q18: T.C | U18: =IF(S18=0,(T18/P18),S18) -> #DIV/0! | V18: =R18*U18 -> #DIV/0! | AB18: Arverjas | AC18: 1 | AD18: cucharon colmado | AH18: =IF(AF18=0,(AG18/AC18),AF18) -> 0 | AI18: =AE18*AH18 -> 0
A19: Comida | C19: Papa | D19: 2 | E19: Unidad | F19: 83 | G19: 2 | I19: =IF(G19=0,(H19/D19),G19) -> 2 | J19: =F19*I19 -> 166 | O19: Infusión frutas | P19: 1 | Q19: Vaso pequeño | S19: 1 | U19: =IF(S19=0,(T19/P19),S19) -> 1 | V19: =R19*U19 -> 0 | AB19: Platano asado | AC19: 1 | AD19: unidad (1/4 del platano) | AE19: 66 | AF19: 2 | AH19: =IF(AF19=0,(AG19/AC19),AF19) -> 2 | AI19: =AE19*AH19 -> 132
A20: Comida | C20: Pimienta | D20: 2 | E20: Cucharaditas | G20: 2 | I20: =IF(G20=0,(H20/D20),G20) -> 2 | J20: =F20*I20 -> 0 | M20: Extra 1 (Media mañana) | O20: Yogurt griego | P20: 0.5 | Q20: Vaso pequeño | S20: 1 | U20: =IF(S20=0,(T20/P20),S20) -> 1 | V20: =R20*U20 -> 0 | AB20: Pimenton | AC20: 1 | AD20: unidad | AF20: 0.5 | AH20: =IF(AF20=0,(AG20/AC20),AF20) -> 0.5 | AI20: =AE20*AH20 -> 0
A21: Comida | C21: Perejil | D21: 1 | E21: Rama | G21: 1 | I21: =IF(G21=0,(H21/D21),G21) -> 1 | J21: =F21*I21 -> 0 | O21: Frutos secos | P21: 4 | Q21: Cucharadas | S21: 1 | U21: =IF(S21=0,(T21/P21),S21) -> 1 | V21: =R21*U21 -> 0 | AB21: Apio | AC21: 1 | AD21: tallo | AF21: 1 | AH21: =IF(AF21=0,(AG21/AC21),AF21) -> 1 | AI21: =AE21*AH21 -> 0
A22: Comida | C22: Limon mediano | D22: 1 | E22: Unidad | G22: 1 | I22: =IF(G22=0,(H22/D22),G22) -> 1 | J22: =F22*I22 -> 0 | O22: Ensalada de fruta (manzana verde, melón, papaya, piña) | P22: 1 | Q22: Vaso pequeño | U22: =IF(S22=0,(T22/P22),S22) -> 0 | V22: =R22*U22 -> 0 | Z22: Media mañana | AB22: Mani | AC22: 1 | AD22: puñado | AH22: =IF(AF22=0,(AG22/AC22),AF22) -> 0 | AI22: =AE22*AH22 -> 0
A23: Comida | C23: Panela molida | D23: 1 | E23: Cucharrada | G23: 1 | I23: =IF(G23=0,(H23/D23),G23) -> 1 | J23: =F23*I23 -> 0 | O23: Infusión frutas | P23: 1 | Q23: Vaso pequeño | S23: 1 | U23: =IF(S23=0,(T23/P23),S23) -> 1 | V23: =R23*U23 -> 0 | AB23: Nuez | AC23: 1 | AD23: puñado | AH23: =IF(AF23=0,(AG23/AC23),AF23) -> 0 | AI23: =AE23*AH23 -> 0
A24: Algo | C24: Yogur griego | D24: 1 | E24: Unidad | F24: 200 | G24: 1 | I24: =IF(G24=0,(H24/D24),G24) -> 1 | J24: =F24*I24 -> 200 | M24: Extra 2 (Algo) | O24: Gelatina | P24: 1 | Q24: Vaso grande | S24: 1 | U24: =IF(S24=0,(T24/P24),S24) -> 1 | V24: =R24*U24 -> 0 | AB24: Almendras | AC24: 1 | AD24: puñado | AH24: =IF(AF24=0,(AG24/AC24),AF24) -> 0 | AI24: =AE24*AH24 -> 0
A25: Algo | C25: Mango | D25: 1 | E25: Unidad | F25: 112 | G25: 1 | I25: =IF(G25=0,(H25/D25),G25) -> 1 | J25: =F25*I25 -> 112 | AB25: Kiwi | AC25: 1 | AD25: unidad | AH25: =IF(AF25=0,(AG25/AC25),AF25) -> 0 | AI25: =AE25*AH25 -> 0
A26: Algo | C26: Granola | D26: 1 | E26: Cucharas | F26: 50 | G26: 1 | I26: =IF(G26=0,(H26/D26),G26) -> 1 | J26: =F26*I26 -> 50 | AB26: Piña | AC26: 1 | AD26: rodaja | AE26: 110 | AF26: 1 | AH26: =IF(AF26=0,(AG26/AC26),AF26) -> 1 | AI26: =AE26*AH26 -> 110
A27: Algo | C27: Crema de maní | D27: 1 | E27: Cucharadas dulceras | F27: 5 | G27: 2 | I27: =IF(G27=0,(H27/D27),G27) -> 2 | J27: =F27*I27 -> 10 | AB27: Manzana | AC27: 1 | AD27: unidad pequeña | AE27: 112 | AF27: 1 | AH27: =IF(AF27=0,(AG27/AC27),AF27) -> 1 | AI27: =AE27*AH27 -> 112
A28: Algo | C28: Avena | D28: 3 | E28: Cucharas soperas | F28: 18 | G28: 1 | I28: =IF(G28=0,(H28/D28),G28) -> 1 | J28: =F28*I28 -> 18 | AB28: Fresas | AC28: 9 | AD28: unidades | AE28: 161 | AG28: 6 | AH28: =IF(AF28=0,(AG28/AC28),AF28) -> 0.66666667 | AI28: =AE28*AH28 -> 107.33333
A29: Desayuno | B29: Frutas | C29: Fresa | D29: 9 | E29: unidades | F29: 161 | H29: 3 | I29: =IF(G29=0,(H29/D29),G29) -> 0.33333333 | J29: =F29*I29 -> 53.666667 | Z29: Por la tarde | AB29: Mani | AC29: 1 | AD29: puñado | AH29: =IF(AF29=0,(AG29/AC29),AF29) -> 0 | AI29: =AE29*AH29 -> 0
A30: Desayuno | C30: Arepa | D30: 1 | E30: Unidad grande | F30: 52 | G30: 1 | I30: =IF(G30=0,(H30/D30),G30) -> 1 | J30: =F30*I30 -> 52 | AB30: Nuez | AC30: 1 | AD30: puñado | AH30: =IF(AF30=0,(AG30/AC30),AF30) -> 0 | AI30: =AE30*AH30 -> 0
A31: Desayuno | C31: Huevos | D31: 1 | E31: Unidad | F31: 50 | G31: 2 | I31: =IF(G31=0,(H31/D31),G31) -> 2 | J31: =F31*I31 -> 100 | AB31: Almendras | AC31: 1 | AD31: puñado | AH31: =IF(AF31=0,(AG31/AC31),AF31) -> 0 | AI31: =AE31*AH31 -> 0
A32: Desayuno | C32: Cuajada | D32: 1 | E32: Tajada pequeña semi gruesa | F32: 20 | G32: 1 | I32: =IF(G32=0,(H32/D32),G32) -> 1 | J32: =F32*I32 -> 20 | AB32: Kiwi | AC32: 1 | AD32: unidad | AH32: =IF(AF32=0,(AG32/AC32),AF32) -> 0 | AI32: =AE32*AH32 -> 0
A33: Desayuno | C33: Jugo de naranja | D33: 1 | E33: Vaso pequeño | F33: 200 | G33: 1 | I33: =IF(G33=0,(H33/D33),G33) -> 1 | J33: =F33*I33 -> 200 | AB33: Piña | AC33: 1 | AD33: rodaja | AE33: 110 | AF33: 1 | AH33: =IF(AF33=0,(AG33/AC33),AF33) -> 1 | AI33: =AE33*AH33 -> 110
A34: Almuerzo | C34: Arroz | D34: 6 | E34: Cucharadas soperas | F34: 80 | G34: 1 | I34: =IF(G34=0,(H34/D34),G34) -> 1 | J34: =F34*I34 -> 80 | AB34: Manzana | AC34: 1 | AD34: unidad pequeña | AE34: 112 | AF34: 1 | AH34: =IF(AF34=0,(AG34/AC34),AF34) -> 1 | AI34: =AE34*AH34 -> 112
A35: Almuerzo | C35: Lentejas | D35: 1 | E35: Cucharon colmado | F35: 130 | G35: 1 | I35: =IF(G35=0,(H35/D35),G35) -> 1 | J35: =F35*I35 -> 130 | AB35: Fresas | AC35: 9 | AD35: unidades | AE35: 161 | AG35: 6 | AH35: =IF(AF35=0,(AG35/AC35),AF35) -> 0.66666667 | AI35: =AE35*AH35 -> 107.33333

Sheet Taller Guarne
C2: Grupo 1 | I2: Rango de edad: 19 a 30 | O2: Grupo 2 | U2: Rango de edad: 31-50 años | AB2: Grupo 3 | AH2: Rango de edad: +50
D4: Grupo | E4: Alimento | F4: Unidad de medida por porción | G4: Medida casera | H4: Gramos porción | I4: Porción elegida | J4: Unidades | K4: Porción final | L4: Cantidad total gramos | M4: Observaciones | P4: Grupo | Q4: Alimento | R4: Unidad de medida | S4: Medida casera | T4: Gramos porción | U4: Porción elegida | V4: Unidades | W4: Porción final | X4: Cantidad total gramos | Y4: Observaciones | AC4: Grupo | AD4: Alimento | AE4: Unidad de medida | AF4: Medida casera | AG4: Gramos porción | AH4: Porción elegida | AI4: Unidades | AJ4: Porción final | AK4: Cantidad total gramos | AL4: Observaciones
C5: Desayuno | D5: Frutas | E5: Arepa blanca | F5: 1 | G5: unidad grande | H5: 52 | I5: 1 | K5: =IF(I5=0,(J5/F5),I5) -> 1 | L5: =K5*H5 -> 52 | O5: Desayuno | P5: Frutas | Q5: Tomate | R5: 1 | S5: unidad mediana | T5: 132 | U5: 1 | W5: =IF(U5=0,(V5/R5),U5) -> 1 | X5: =T5*W5 -> 132 | AB5: Desayuno | AD5: Quesito | AE5: 1 | AF5: tajada pequeña | AG5: 30 | AH5: 1 | AJ5: =IF(AH5=0,(AI5/AE5),AH5) -> 1 | AK5: =AG5*AJ5 -> 30
D6: Grasas | E6: Chocolate caliente en agua | F6: 1 | G6: mug | H6: 300 | I6: 1 | K6: =IF(I6=0,(J6/F6),I6) -> 1 | L6: =K6*H6 -> 300 | Q6: Cebolla | U6: 0.5 | W6: =IF(U6=0,(V6/R6),U6) -> 0.5 | X6: =T6*W6 -> 0 | AD6: Huevo con aliños | AE6: 1 | AF6: unidad | AG6: 50 | AH6: 2 | AJ6: =IF(AH6=0,(AI6/AE6),AH6) -> 2 | AK6: =AG6*AJ6 -> 100
D7: Leguminosas | E7: Quesito | F7: 1 | G7: tajada pequeña semigruesa | H7: 30 | I7: 1 | K7: =IF(I7=0,(J7/F7),I7) -> 1 | L7: =K7*H7 -> 30 | Q7: Sal de mar | W7: =IF(U7=0,(V7/R7),U7) -> #DIV/0! | X7: =T7*W7 -> #DIV/0! | Y7: 1 pizca | AD7: Mantequilla | AE7: 1 | AF7: cucharada dulcera | AJ7: =IF(AH7=0,(AI7/AE7),AH7) -> 0 | AK7: =AG7*AJ7 -> 0
